Traceback (most recent call last):
  File "/home/jlovering/emu/lib/python3.7/site-packages/pandas/core/indexes/base.py", line 2889, in get_loc
    return self._engine.get_loc(casted_key)
  File "pandas/_libs/index.pyx", line 70, in pandas._libs.index.IndexEngine.get_loc
  File "pandas/_libs/index.pyx", line 97, in pandas._libs.index.IndexEngine.get_loc
  File "pandas/_libs/hashtable_class_helper.pxi", line 1675, in pandas._libs.hashtable.PyObjectHashTable.get_item
  File "pandas/_libs/hashtable_class_helper.pxi", line 1683, in pandas._libs.hashtable.PyObjectHashTable.get_item
KeyError: 'target'

The above exception was the direct cause of the following exception:

Traceback (most recent call last):
  File "run_models.py", line 536, in <module>
    main()
  File "run_models.py", line 367, in main
    target = target['target'].values.tolist()
  File "/home/jlovering/emu/lib/python3.7/site-packages/pandas/core/frame.py", line 2899, in __getitem__
    indexer = self.columns.get_loc(key)
  File "/home/jlovering/emu/lib/python3.7/site-packages/pandas/core/indexes/base.py", line 2891, in get_loc
    raise KeyError(key) from err
KeyError: 'target'
Traceback (most recent call last):
  File "/home/jlovering/emu/lib/python3.7/site-packages/pandas/core/indexes/base.py", line 2889, in get_loc
    return self._engine.get_loc(casted_key)
  File "pandas/_libs/index.pyx", line 70, in pandas._libs.index.IndexEngine.get_loc
  File "pandas/_libs/index.pyx", line 97, in pandas._libs.index.IndexEngine.get_loc
  File "pandas/_libs/hashtable_class_helper.pxi", line 1675, in pandas._libs.hashtable.PyObjectHashTable.get_item
  File "pandas/_libs/hashtable_class_helper.pxi", line 1683, in pandas._libs.hashtable.PyObjectHashTable.get_item
KeyError: 'target'

The above exception was the direct cause of the following exception:

Traceback (most recent call last):
  File "run_models.py", line 536, in <module>
    main()
  File "run_models.py", line 367, in main
    target = target['target'].values.tolist()
  File "/home/jlovering/emu/lib/python3.7/site-packages/pandas/core/frame.py", line 2899, in __getitem__
    indexer = self.columns.get_loc(key)
  File "/home/jlovering/emu/lib/python3.7/site-packages/pandas/core/indexes/base.py", line 2891, in get_loc
    raise KeyError(key) from err
KeyError: 'target'
Traceback (most recent call last):
  File "/home/jlovering/emu/lib/python3.7/site-packages/pandas/core/indexes/base.py", line 2889, in get_loc
    return self._engine.get_loc(casted_key)
  File "pandas/_libs/index.pyx", line 70, in pandas._libs.index.IndexEngine.get_loc
  File "pandas/_libs/index.pyx", line 97, in pandas._libs.index.IndexEngine.get_loc
  File "pandas/_libs/hashtable_class_helper.pxi", line 1675, in pandas._libs.hashtable.PyObjectHashTable.get_item
  File "pandas/_libs/hashtable_class_helper.pxi", line 1683, in pandas._libs.hashtable.PyObjectHashTable.get_item
KeyError: 'target'

The above exception was the direct cause of the following exception:

Traceback (most recent call last):
  File "run_models.py", line 536, in <module>
    main()
  File "run_models.py", line 367, in main
    target = target['target'].values.tolist()
  File "/home/jlovering/emu/lib/python3.7/site-packages/pandas/core/frame.py", line 2899, in __getitem__
    indexer = self.columns.get_loc(key)
  File "/home/jlovering/emu/lib/python3.7/site-packages/pandas/core/indexes/base.py", line 2891, in get_loc
    raise KeyError(key) from err
KeyError: 'target'
